Workbook

Sheet Fase de Grupos
A1: GROUP A · ¡Salinator por Chequia! 🇨🇿
I2: # | J2: Team | K2: GP | L2: W | M2: D | N2: L | O2: GF | P2: GA | Q2: GD | R2: Pts
J3: Mexico | K3: =IF(AND(D9<>"",E9<>""),1,0)+IF(AND(D12<>"",E12<>""),1,0)+IF(AND(D13<>"",E13<>""),1,0) | L3: =IF(AND(D9<>"",E9<>"",D9>E9),1,0)+IF(AND(D12<>"",E12<>"",D12>E12),1,0)+IF(AND(D13<>"",E13<>"",E13>D13),1,0) | M3: =IF(AND(D9<>"",E9<>"",D9=E9),1,0)+IF(AND(D12<>"",E12<>"",D12=E12),1,0)+IF(AND(D13<>"",E13<>"",D13=E13),1,0) | N3: =IF(AND(D9<>"",E9<>"",D9<E9),1,0)+IF(AND(D12<>"",E12<>"",D12<E12),1,0)+IF(AND(D13<>"",E13<>"",E13<D13),1,0) | O3: =IF(AND(D9<>"",E9<>""),D9,0)+IF(AND(D12<>"",E12<>""),D12,0)+IF(AND(D13<>"",E13<>""),E13,0) | P3: =IF(AND(D9<>"",E9<>""),E9,0)+IF(AND(D12<>"",E12<>""),E12,0)+IF(AND(D13<>"",E13<>""),D13,0) | Q3: =O3-P3 | R3: =3*L3+M3 | S3: =R3*10000000+(Q3+99)*100000+O3*100+4
J4: South Korea | K4: =IF(AND(D10<>"",E10<>""),1,0)+IF(AND(D12<>"",E12<>""),1,0)+IF(AND(D14<>"",E14<>""),1,0) | L4: =IF(AND(D10<>"",E10<>"",D10>E10),1,0)+IF(AND(D12<>"",E12<>"",E12>D12),1,0)+IF(AND(D14<>"",E14<>"",E14>D14),1,0) | M4: =IF(AND(D10<>"",E10<>"",D10=E10),1,0)+IF(AND(D12<>"",E12<>"",D12=E12),1,0)+IF(AND(D14<>"",E14<>"",D14=E14),1,0) | N4: =IF(AND(D10<>"",E10<>"",D10<E10),1,0)+IF(AND(D12<>"",E12<>"",E12<D12),1,0)+IF(AND(D14<>"",E14<>"",E14<D14),1,0) | O4: =IF(AND(D10<>"",E10<>""),D10,0)+IF(AND(D12<>"",E12<>""),E12,0)+IF(AND(D14<>"",E14<>""),E14,0) | P4: =IF(AND(D10<>"",E10<>""),E10,0)+IF(AND(D12<>"",E12<>""),D12,0)+IF(AND(D14<>"",E14<>""),D14,0) | Q4: =O4-P4 | R4: =3*L4+M4 | S4: =R4*10000000+(Q4+99)*100000+O4*100+3
J5: South Africa | K5: =IF(AND(D14<>"",E14<>""),1,0)+IF(AND(D9<>"",E9<>""),1,0)+IF(AND(D11<>"",E11<>""),1,0) | L5: =IF(AND(D14<>"",E14<>"",D14>E14),1,0)+IF(AND(D9<>"",E9<>"",E9>D9),1,0)+IF(AND(D11<>"",E11<>"",E11>D11),1,0) | M5: =IF(AND(D14<>"",E14<>"",D14=E14),1,0)+IF(AND(D9<>"",E9<>"",D9=E9),1,0)+IF(AND(D11<>"",E11<>"",D11=E11),1,0) | N5: =IF(AND(D14<>"",E14<>"",D14<E14),1,0)+IF(AND(D9<>"",E9<>"",E9<D9),1,0)+IF(AND(D11<>"",E11<>"",E11<D11),1,0) | O5: =IF(AND(D14<>"",E14<>""),D14,0)+IF(AND(D9<>"",E9<>""),E9,0)+IF(AND(D11<>"",E11<>""),E11,0) | P5: =IF(AND(D14<>"",E14<>""),E14,0)+IF(AND(D9<>"",E9<>""),D9,0)+IF(AND(D11<>"",E11<>""),D11,0) | Q5: =O5-P5 | R5: =3*L5+M5 | S5: =R5*10000000+(Q5+99)*100000+O5*100+2
J6: Czech Republic | K6: =IF(AND(D11<>"",E11<>""),1,0)+IF(AND(D13<>"",E13<>""),1,0)+IF(AND(D10<>"",E10<>""),1,0) | L6: =IF(AND(D11<>"",E11<>"",D11>E11),1,0)+IF(AND(D13<>"",E13<>"",D13>E13),1,0)+IF(AND(D10<>"",E10<>"",E10>D10),1,0) | M6: =IF(AND(D11<>"",E11<>"",D11=E11),1,0)+IF(AND(D13<>"",E13<>"",D13=E13),1,0)+IF(AND(D10<>"",E10<>"",D10=E10),1,0) | N6: =IF(AND(D11<>"",E11<>"",D11<E11),1,0)+IF(AND(D13<>"",E13<>"",D13<E13),1,0)+IF(AND(D10<>"",E10<>"",E10<D10),1,0) | O6: =IF(AND(D11<>"",E11<>""),D11,0)+IF(AND(D13<>"",E13<>""),D13,0)+IF(AND(D10<>"",E10<>""),E10,0) | P6: =IF(AND(D11<>"",E11<>""),E11,0)+IF(AND(D13<>"",E13<>""),E13,0)+IF(AND(D10<>"",E10<>""),D10,0) | Q6: =O6-P6 | R6: =3*L6+M6 | S6: =R6*10000000+(Q6+99)*100000+O6*100+1
A8: MD | B8: Date / Time (ET) | C8: Home Team | D8: G | E8: G | F8: Away Team | G8: Venue
A9: 1 | B9: Jun 11 · 3 pm ET | C9: Mexico | D9: =RANDBETWEEN(0,4) | E9: =RANDBETWEEN(0,4) | F9: South Africa | G9: Mexico City
A10: 1 | B10: Jun 11 · 10 pm ET | C10: South Korea | D10: =RANDBETWEEN(0,4) | E10: =RANDBETWEEN(0,4) | F10: Czech Republic | G10: Guadalajara
A11: 2 | B11: Jun 18 · 12 pm ET | C11: Czech Republic | D11: =RANDBETWEEN(0,4) | E11: =RANDBETWEEN(0,4) | F11: South Africa | G11: Atlanta
A12: 2 | B12: Jun 18 · 9 pm ET | C12: Mexico | D12: =RANDBETWEEN(0,4) | E12: =RANDBETWEEN(0,4) | F12: South Korea | G12: Guadalajara
A13: 3 | B13: Jun 24 · 9 pm ET | C13: Czech Republic | D13: =RANDBETWEEN(0,4) | E13: =RANDBETWEEN(0,4) | F13: Mexico | G13: Mexico City
A14: 3 | B14: Jun 24 · 9 pm ET | C14: South Africa | D14: =RANDBETWEEN(0,4) | E14: =RANDBETWEEN(0,4) | F14: South Korea | G14: Monterrey
A17: GROUP B
I18: # | J18: Team | K18: GP | L18: W | M18: D | N18: L | O18: GF | P18: GA | Q18: GD | R18: Pts
J19: Canada | K19: =IF(AND(D25<>"",E25<>""),1,0)+IF(AND(D28<>"",E28<>""),1,0)+IF(AND(D29<>"",E29<>""),1,0) | L19: =IF(AND(D25<>"",E25<>"",D25>E25),1,0)+IF(AND(D28<>"",E28<>"",D28>E28),1,0)+IF(AND(D29<>"",E29<>"",D29>E29),1,0) | M19: =IF(AND(D25<>"",E25<>"",D25=E25),1,0)+IF(AND(D28<>"",E28<>"",D28=E28),1,0)+IF(AND(D29<>"",E29<>"",D29=E29),1,0) | N19: =IF(AND(D25<>"",E25<>"",D25<E25),1,0)+IF(AND(D28<>"",E28<>"",D28<E28),1,0)+IF(AND(D29<>"",E29<>"",D29<E29),1,0) | O19: =IF(AND(D25<>"",E25<>""),D25,0)+IF(AND(D28<>"",E28<>""),D28,0)+IF(AND(D29<>"",E29<>""),D29,0)+0 | P19: =IF(AND(D25<>"",E25<>""),E25,0)+IF(AND(D28<>"",E28<>""),E28,0)+IF(AND(D29<>"",E29<>""),E29,0)+0 | Q19: =O19-P19 | R19: =3*L19+M19 | S19: =R19*10000000+(Q19+99)*100000+O19*100+4
J20: Switzerland | K20: =IF(AND(D27<>"",E27<>""),1,0)+IF(AND(D26<>"",E26<>""),1,0)+IF(AND(D29<>"",E29<>""),1,0) | L20: =IF(AND(D27<>"",E27<>"",D27>E27),1,0)+IF(AND(D26<>"",E26<>"",E26>D26),1,0)+IF(AND(D29<>"",E29<>"",E29>D29),1,0) | M20: =IF(AND(D27<>"",E27<>"",D27=E27),1,0)+IF(AND(D26<>"",E26<>"",D26=E26),1,0)+IF(AND(D29<>"",E29<>"",D29=E29),1,0) | N20: =IF(AND(D27<>"",E27<>"",D27<E27),1,0)+IF(AND(D26<>"",E26<>"",E26<D26),1,0)+IF(AND(D29<>"",E29<>"",E29<D29),1,0) | O20: =IF(AND(D27<>"",E27<>""),D27,0)+IF(AND(D26<>"",E26<>""),E26,0)+IF(AND(D29<>"",E29<>""),E29,0) | P20: =IF(AND(D27<>"",E27<>""),E27,0)+IF(AND(D26<>"",E26<>""),D26,0)+IF(AND(D29<>"",E29<>""),D29,0) | Q20: =O20-P20 | R20: =3*L20+M20 | S20: =R20*10000000+(Q20+99)*100000+O20*100+3
J21: Qatar | K21: =IF(AND(D26<>"",E26<>""),1,0)+IF(AND(D28<>"",E28<>""),1,0)+IF(AND(D30<>"",E30<>""),1,0) | L21: =IF(AND(D26<>"",E26<>"",D26>E26),1,0)+IF(AND(D28<>"",E28<>"",E28>D28),1,0)+IF(AND(D30<>"",E30<>"",E30>D30),1,0) | M21: =IF(AND(D26<>"",E26<>"",D26=E26),1,0)+IF(AND(D28<>"",E28<>"",D28=E28),1,0)+IF(AND(D30<>"",E30<>"",D30=E30),1,0) | N21: =IF(AND(D26<>"",E26<>"",D26<E26),1,0)+IF(AND(D28<>"",E28<>"",E28<D28),1,0)+IF(AND(D30<>"",E30<>"",E30<D30),1,0) | O21: =IF(AND(D26<>"",E26<>""),D26,0)+IF(AND(D28<>"",E28<>""),E28,0)+IF(AND(D30<>"",E30<>""),E30,0) | P21: =IF(AND(D26<>"",E26<>""),E26,0)+IF(AND(D28<>"",E28<>""),D28,0)+IF(AND(D30<>"",E30<>""),D30,0) | Q21: =O21-P21 | R21: =3*L21+M21 | S21: =R21*10000000+(Q21+99)*100000+O21*100+2
J22: Bosnia & Herzegovina | K22: =IF(AND(D30<>"",E30<>""),1,0)+IF(AND(D25<>"",E25<>""),1,0)+IF(AND(D27<>"",E27<>""),1,0) | L22: =IF(AND(D30<>"",E30<>"",D30>E30),1,0)+IF(AND(D25<>"",E25<>"",E25>D25),1,0)+IF(AND(D27<>"",E27<>"",E27>D27),1,0) | M22: =IF(AND(D30<>"",E30<>"",D30=E30),1,0)+IF(AND(D25<>"",E25<>"",D25=E25),1,0)+IF(AND(D27<>"",E27<>"",D27=E27),1,0) | N22: =IF(AND(D30<>"",E30<>"",D30<E30),1,0)+IF(AND(D25<>"",E25<>"",E25<D25),1,0)+IF(AND(D27<>"",E27<>"",E27<D27),1,0) | O22: =IF(AND(D30<>"",E30<>""),D30,0)+IF(AND(D25<>"",E25<>""),E25,0)+IF(AND(D27<>"",E27<>""),E27,0) | P22: =IF(AND(D30<>"",E30<>""),E30,0)+IF(AND(D25<>"",E25<>""),D25,0)+IF(AND(D27<>"",E27<>""),D27,0) | Q22: =O22-P22 | R22: =3*L22+M22 | S22: =R22*10000000+(Q22+99)*100000+O22*100+1
A24: MD | B24: Date / Time (ET) | C24: Home Team | D24: G | E24: G | F24: Away Team | G24: Venue
A25: 1 | B25: Jun 12 · 3 pm ET | C25: Canada | D25: =RANDBETWEEN(0,4) | E25: =RANDBETWEEN(0,4) | F25: Bosnia & Herzegovina | G25: Toronto
A26: 1 | B26: Jun 13 · 3 pm ET | C26: Qatar | D26: =RANDBETWEEN(0,4) | E26: =RANDBETWEEN(0,4) | F26: Switzerland | G26: San Francisco
A27: 2 | B27: Jun 18 · 3 pm ET | C27: Switzerland | D27: =RANDBETWEEN(0,4) | E27: =RANDBETWEEN(0,4) | F27: Bosnia & Herzegovina | G27: Los Angeles
A28: 2 | B28: Jun 18 · 6 pm ET | C28: Canada | D28: =RANDBETWEEN(0,4) | E28: =RANDBETWEEN(0,4) | F28: Qatar | G28: Vancouver
A29: 3 | B29: Jun 24 · 3 pm ET | C29: Canada | D29: =RANDBETWEEN(0,4) | E29: =RANDBETWEEN(0,4) | F29: Switzerland | G29: Vancouver
A30: 3 | B30: Jun 24 · 3 pm ET | C30: Bosnia & Herzegovina | D30: =RANDBETWEEN(0,4) | E30: =RANDBETWEEN(0,4) | F30: Qatar | G30: Seattle
A33: GROUP C
I34: # | J34: Team | K34: GP | L34: W | M34: D | N34: L | O34: GF | P34: GA | Q34: GD | R34: Pts
J35: Brazil | K35: =IF(AND(D41<>"",E41<>""),1,0)+IF(AND(D44<>"",E44<>""),1,0)+IF(AND(D45<>"",E45<>""),1,0) | L35: =IF(AND(D41<>"",E41<>"",D41>E41),1,0)+IF(AND(D44<>"",E44<>"",D44>E44),1,0)+IF(AND(D45<>"",E45<>"",E45>D45),1,0) | M35: =IF(AND(D41<>"",E41<>"",D41=E41),1,0)+IF(AND(D44<>"",E44<>"",D44=E44),1,0)+IF(AND(D45<>"",E45<>"",D45=E45),1,0) | N35: =IF(AND(D41<>"",E41<>"",D41<E41),1,0)+IF(AND(D44<>"",E44<>"",D44<E44),1,0)+IF(AND(D45<>"",E45<>"",E45<D45),1,0) | O35: =IF(AND(D41<>"",E41<>""),D41,0)+IF(AND(D44<>"",E44<>""),D44,0)+IF(AND(D45<>"",E45<>""),E45,0) | P35: =IF(AND(D41<>"",E41<>""),E41,0)+IF(AND(D44<>"",E44<>""),E44,0)+IF(AND(D45<>"",E45<>""),D45,0) | Q35: =O35-P35 | R35: =3*L35+M35 | S35: =R35*10000000+(Q35+99)*100000+O35*100+4
J36: Morocco | K36: =IF(AND(D46<>"",E46<>""),1,0)+IF(AND(D41<>"",E41<>""),1,0)+IF(AND(D43<>"",E43<>""),1,0) | L36: =IF(AND(D46<>"",E46<>"",D46>E46),1,0)+IF(AND(D41<>"",E41<>"",E41>D41),1,0)+IF(AND(D43<>"",E43<>"",E43>D43),1,0) | M36: =IF(AND(D46<>"",E46<>"",D46=E46),1,0)+IF(AND(D41<>"",E41<>"",D41=E41),1,0)+IF(AND(D43<>"",E43<>"",D43=E43),1,0) | N36: =IF(AND(D46<>"",E46<>"",D46<E46),1,0)+IF(AND(D41<>"",E41<>"",E41<D41),1,0)+IF(AND(D43<>"",E43<>"",E43<D43),1,0) | O36: =IF(AND(D46<>"",E46<>""),D46,0)+IF(AND(D41<>"",E41<>""),E41,0)+IF(AND(D43<>"",E43<>""),E43,0) | P36: =IF(AND(D46<>"",E46<>""),E46,0)+IF(AND(D41<>"",E41<>""),D41,0)+IF(AND(D43<>"",E43<>""),D43,0) | Q36: =O36-P36 | R36: =3*L36+M36 | S36: =R36*10000000+(Q36+99)*100000+O36*100+3
J37: Scotland | K37: =IF(AND(D43<>"",E43<>""),1,0)+IF(AND(D45<>"",E45<>""),1,0)+IF(AND(D42<>"",E42<>""),1,0) | L37: =IF(AND(D43<>"",E43<>"",D43>E43),1,0)+IF(AND(D45<>"",E45<>"",D45>E45),1,0)+IF(AND(D42<>"",E42<>"",E42>D42),1,0) | M37: =IF(AND(D43<>"",E43<>"",D43=E43),1,0)+IF(AND(D45<>"",E45<>"",D45=E45),1,0)+IF(AND(D42<>"",E42<>"",D42=E42),1,0) | N37: =IF(AND(D43<>"",E43<>"",D43<E43),1,0)+IF(AND(D45<>"",E45<>"",D45<E45),1,0)+IF(AND(D42<>"",E42<>"",E42<D42),1,0) | O37: =IF(AND(D43<>"",E43<>""),D43,0)+IF(AND(D45<>"",E45<>""),D45,0)+IF(AND(D42<>"",E42<>""),E42,0) | P37: =IF(AND(D43<>"",E43<>""),E43,0)+IF(AND(D45<>"",E45<>""),E45,0)+IF(AND(D42<>"",E42<>""),D42,0) | Q37: =O37-P37 | R37: =3*L37+M37 | S37: =R37*10000000+(Q37+99)*100000+O37*100+2
J38: Haiti | K38: =IF(AND(D42<>"",E42<>""),1,0)+IF(AND(D44<>"",E44<>""),1,0)+IF(AND(D46<>"",E46<>""),1,0) | L38: =IF(AND(D42<>"",E42<>"",D42>E42),1,0)+IF(AND(D44<>"",E44<>"",E44>D44),1,0)+IF(AND(D46<>"",E46<>"",E46>D46),1,0) | M38: =IF(AND(D42<>"",E42<>"",D42=E42),1,0)+IF(AND(D44<>"",E44<>"",D44=E44),1,0)+IF(AND(D46<>"",E46<>"",D46=E46),1,0) | N38: =IF(AND(D42<>"",E42<>"",D42<E42),1,0)+IF(AND(D44<>"",E44<>"",E44<D44),1,0)+IF(AND(D46<>"",E46<>"",E46<D46),1,0) | O38: =IF(AND(D42<>"",E42<>""),D42,0)+IF(AND(D44<>"",E44<>""),E44,0)+IF(AND(D46<>"",E46<>""),E46,0) | P38: =IF(AND(D42<>"",E42<>""),E42,0)+IF(AND(D44<>"",E44<>""),D44,0)+IF(AND(D46<>"",E46<>""),D46,0) | Q38: =O38-P38 | R38: =3*L38+M38 | S38: =R38*10000000+(Q38+99)*100000+O38*100+1
A40: MD | B40: Date / Time (ET) | C40: Home Team | D40: G | E40: G | F40: Away Team | G40: Venue
A41: 1 | B41: Jun 13 · 6 pm ET | C41: Brazil | D41: =RANDBETWEEN(0,4) | E41: =RANDBETWEEN(0,4) | F41: Morocco | G41: New York/NJ
A42: 1 | B42: Jun 13 · 9 pm ET | C42: Haiti | D42: =RANDBETWEEN(0,4) | E42: =RANDBETWEEN(0,4) | F42: Scotland | G42: Boston
A43: 2 | B43: Jun 19 · 3 pm ET | C43: Scotland | D43: =RANDBETWEEN(0,4) | E43: =RANDBETWEEN(0,4) | F43: Morocco | G43: Boston
A44: 2 | B44: Jun 19 · 9 pm ET | C44: Brazil | D44: =RANDBETWEEN(0,4) | E44: =RANDBETWEEN(0,4) | F44: Haiti | G44: Philadelphia
A45: 3 | B45: Jun 24 · 6 pm ET | C45: Scotland | D45: =RANDBETWEEN(0,4) | E45: =RANDBETWEEN(0,4) | F45: Brazil | G45: Miami
A46: 3 | B46: Jun 24 · 6 pm ET | C46: Morocco | D46: =RANDBETWEEN(0,4) | E46: =RANDBETWEEN(0,4) | F46: Haiti | G46: Atlanta
A49: GROUP D
...

Sheet Clasificados
A1: 🏟️ Clasificados · Qualified Teams
A2: Rankings update automatically as you enter scores in the Fase de Grupos tab.
A3: Group | B3: 1st Place ✅ | C3: 2nd Place ✅ | D3: 3rd Place ⚠️ | E3: 4th Place ❌
A4: Group A | B4: =IFERROR(INDEX('Fase de Grupos'!$J$3:$J$6,MATCH(LARGE('Fase de Grupos'!$S$3:$S$6,1),'Fase de Grupos'!$S$3:$S$6,0)),"—") | C4: =IFERROR(INDEX('Fase de Grupos'!$J$3:$J$6,MATCH(LARGE('Fase de Grupos'!$S$3:$S$6,2),'Fase de Grupos'!$S$3:$S$6,0)),"—") | D4: =IFERROR(INDEX('Fase de Grupos'!$J$3:$J$6,MATCH(LARGE('Fase de Grupos'!$S$3:$S$6,3),'Fase de Grupos'!$S$3:$S$6,0)),"—") | E4: =IFERROR(INDEX('Fase de Grupos'!$J$3:$J$6,MATCH(LARGE('Fase de Grupos'!$S$3:$S$6,4),'Fase de Grupos'!$S$3:$S$6,0)),"—")
A5: Group B | B5: =IFERROR(INDEX('Fase de Grupos'!$J$19:$J$22,MATCH(LARGE('Fase de Grupos'!$S$19:$S$22,1),'Fase de Grupos'!$S$19:$S$22,0)),"—") | C5: =IFERROR(INDEX('Fase de Grupos'!$J$19:$J$22,MATCH(LARGE('Fase de Grupos'!$S$19:$S$22,2),'Fase de Grupos'!$S$19:$S$22,0)),"—") | D5: =IFERROR(INDEX('Fase de Grupos'!$J$19:$J$22,MATCH(LARGE('Fase de Grupos'!$S$19:$S$22,3),'Fase de Grupos'!$S$19:$S$22,0)),"—") | E5: =IFERROR(INDEX('Fase de Grupos'!$J$19:$J$22,MATCH(LARGE('Fase de Grupos'!$S$19:$S$22,4),'Fase de Grupos'!$S$19:$S$22,0)),"—")
A6: Group C | B6: =IFERROR(INDEX('Fase de Grupos'!$J$35:$J$38,MATCH(LARGE('Fase de Grupos'!$S$35:$S$38,1),'Fase de Grupos'!$S$35:$S$38,0)),"—") | C6: =IFERROR(INDEX('Fase de Grupos'!$J$35:$J$38,MATCH(LARGE('Fase de Grupos'!$S$35:$S$38,2),'Fase de Grupos'!$S$35:$S$38,0)),"—") | D6: =IFERROR(INDEX('Fase de Grupos'!$J$35:$J$38,MATCH(LARGE('Fase de Grupos'!$S$35:$S$38,3),'Fase de Grupos'!$S$35:$S$38,0)),"—") | E6: =IFERROR(INDEX('Fase de Grupos'!$J$35:$J$38,MATCH(LARGE('Fase de Grupos'!$S$35:$S$38,4),'Fase de Grupos'!$S$35:$S$38,0)),"—")
A7: Group D | B7: =IFERROR(INDEX('Fase de Grupos'!$J$51:$J$54,MATCH(LARGE('Fase de Grupos'!$S$51:$S$54,1),'Fase de Grupos'!$S$51:$S$54,0)),"—") | C7: =IFERROR(INDEX('Fase de Grupos'!$J$51:$J$54,MATCH(LARGE('Fase de Grupos'!$S$51:$S$54,2),'Fase de Grupos'!$S$51:$S$54,0)),"—") | D7: =IFERROR(INDEX('Fase de Grupos'!$J$51:$J$54,MATCH(LARGE('Fase de Grupos'!$S$51:$S$54,3),'Fase de Grupos'!$S$51:$S$54,0)),"—") | E7: =IFERROR(INDEX('Fase de Grupos'!$J$51:$J$54,MATCH(LARGE('Fase de Grupos'!$S$51:$S$54,4),'Fase de Grupos'!$S$51:$S$54,0)),"—")
A8: Group E | B8: =IFERROR(INDEX('Fase de Grupos'!$J$67:$J$70,MATCH(LARGE('Fase de Grupos'!$S$67:$S$70,1),'Fase de Grupos'!$S$67:$S$70,0)),"—") | C8: =IFERROR(INDEX('Fase de Grupos'!$J$67:$J$70,MATCH(LARGE('Fase de Grupos'!$S$67:$S$70,2),'Fase de Grupos'!$S$67:$S$70,0)),"—") | D8: =IFERROR(INDEX('Fase de Grupos'!$J$67:$J$70,MATCH(LARGE('Fase de Grupos'!$S$67:$S$70,3),'Fase de Grupos'!$S$67:$S$70,0)),"—") | E8: =IFERROR(INDEX('Fase de Grupos'!$J$67:$J$70,MATCH(LARGE('Fase de Grupos'!$S$67:$S$70,4),'Fase de Grupos'!$S$67:$S$70,0)),"—")
A9: Group F | B9: =IFERROR(INDEX('Fase de Grupos'!$J$83:$J$86,MATCH(LARGE('Fase de Grupos'!$S$83:$S$86,1),'Fase de Grupos'!$S$83:$S$86,0)),"—") | C9: =IFERROR(INDEX('Fase de Grupos'!$J$83:$J$86,MATCH(LARGE('Fase de Grupos'!$S$83:$S$86,2),'Fase de Grupos'!$S$83:$S$86,0)),"—") | D9: =IFERROR(INDEX('Fase de Grupos'!$J$83:$J$86,MATCH(LARGE('Fase de Grupos'!$S$83:$S$86,3),'Fase de Grupos'!$S$83:$S$86,0)),"—") | E9: =IFERROR(INDEX('Fase de Grupos'!$J$83:$J$86,MATCH(LARGE('Fase de Grupos'!$S$83:$S$86,4),'Fase de Grupos'!$S$83:$S$86,0)),"—")
A10: Group G | B10: =IFERROR(INDEX('Fase de Grupos'!$J$99:$J$102,MATCH(LARGE('Fase de Grupos'!$S$99:$S$102,1),'Fase de Grupos'!$S$99:$S$102,0)),"—") | C10: =IFERROR(INDEX('Fase de Grupos'!$J$99:$J$102,MATCH(LARGE('Fase de Grupos'!$S$99:$S$102,2),'Fase de Grupos'!$S$99:$S$102,0)),"—") | D10: =IFERROR(INDEX('Fase de Grupos'!$J$99:$J$102,MATCH(LARGE('Fase de Grupos'!$S$99:$S$102,3),'Fase de Grupos'!$S$99:$S$102,0)),"—") | E10: =IFERROR(INDEX('Fase de Grupos'!$J$99:$J$102,MATCH(LARGE('Fase de Grupos'!$S$99:$S$102,4),'Fase de Grupos'!$S$99:$S$102,0)),"—")
A11: Group H | B11: =IFERROR(INDEX('Fase de Grupos'!$J$115:$J$118,MATCH(LARGE('Fase de Grupos'!$S$115:$S$118,1),'Fase de Grupos'!$S$115:$S$118,0)),"—") | C11: =IFERROR(INDEX('Fase de Grupos'!$J$115:$J$118,MATCH(LARGE('Fase de Grupos'!$S$115:$S$118,2),'Fase de Grupos'!$S$115:$S$118,0)),"—") | D11: =IFERROR(INDEX('Fase de Grupos'!$J$115:$J$118,MATCH(LARGE('Fase de Grupos'!$S$115:$S$118,3),'Fase de Grupos'!$S$115:$S$118,0)),"—") | E11: =IFERROR(INDEX('Fase de Grupos'!$J$115:$J$118,MATCH(LARGE('Fase de Grupos'!$S$115:$S$118,4),'Fase de Grupos'!$S$115:$S$118,0)),"—")
A12: Group I | B12: =IFERROR(INDEX('Fase de Grupos'!$J$131:$J$134,MATCH(LARGE('Fase de Grupos'!$S$131:$S$134,1),'Fase de Grupos'!$S$131:$S$134,0)),"—") | C12: =IFERROR(INDEX('Fase de Grupos'!$J$131:$J$134,MATCH(LARGE('Fase de Grupos'!$S$131:$S$134,2),'Fase de Grupos'!$S$131:$S$134,0)),"—") | D12: =IFERROR(INDEX('Fase de Grupos'!$J$131:$J$134,MATCH(LARGE('Fase de Grupos'!$S$131:$S$134,3),'Fase de Grupos'!$S$131:$S$134,0)),"—") | E12: =IFERROR(INDEX('Fase de Grupos'!$J$131:$J$134,MATCH(LARGE('Fase de Grupos'!$S$131:$S$134,4),'Fase de Grupos'!$S$131:$S$134,0)),"—")
A13: Group J | B13: =IFERROR(INDEX('Fase de Grupos'!$J$147:$J$150,MATCH(LARGE('Fase de Grupos'!$S$147:$S$150,1),'Fase de Grupos'!$S$147:$S$150,0)),"—") | C13: =IFERROR(INDEX('Fase de Grupos'!$J$147:$J$150,MATCH(LARGE('Fase de Grupos'!$S$147:$S$150,2),'Fase de Grupos'!$S$147:$S$150,0)),"—") | D13: =IFERROR(INDEX('Fase de Grupos'!$J$147:$J$150,MATCH(LARGE('Fase de Grupos'!$S$147:$S$150,3),'Fase de Grupos'!$S$147:$S$150,0)),"—") | E13: =IFERROR(INDEX('Fase de Grupos'!$J$147:$J$150,MATCH(LARGE('Fase de Grupos'!$S$147:$S$150,4),'Fase de Grupos'!$S$147:$S$150,0)),"—")
A14: Group K | B14: =IFERROR(INDEX('Fase de Grupos'!$J$163:$J$166,MATCH(LARGE('Fase de Grupos'!$S$163:$S$166,1),'Fase de Grupos'!$S$163:$S$166,0)),"—") | C14: =IFERROR(INDEX('Fase de Grupos'!$J$163:$J$166,MATCH(LARGE('Fase de Grupos'!$S$163:$S$166,2),'Fase de Grupos'!$S$163:$S$166,0)),"—") | D14: =IFERROR(INDEX('Fase de Grupos'!$J$163:$J$166,MATCH(LARGE('Fase de Grupos'!$S$163:$S$166,3),'Fase de Grupos'!$S$163:$S$166,0)),"—") | E14: =IFERROR(INDEX('Fase de Grupos'!$J$163:$J$166,MATCH(LARGE('Fase de Grupos'!$S$163:$S$166,4),'Fase de Grupos'!$S$163:$S$166,0)),"—")
A15: Group L | B15: =IFERROR(INDEX('Fase de Grupos'!$J$179:$J$182,MATCH(LARGE('Fase de Grupos'!$S$179:$S$182,1),'Fase de Grupos'!$S$179:$S$182,0)),"—") | C15: =IFERROR(INDEX('Fase de Grupos'!$J$179:$J$182,MATCH(LARGE('Fase de Grupos'!$S$179:$S$182,2),'Fase de Grupos'!$S$179:$S$182,0)),"—") | D15: =IFERROR(INDEX('Fase de Grupos'!$J$179:$J$182,MATCH(LARGE('Fase de Grupos'!$S$179:$S$182,3),'Fase de Grupos'!$S$179:$S$182,0)),"—") | E15: =IFERROR(INDEX('Fase de Grupos'!$J$179:$J$182,MATCH(LARGE('Fase de Grupos'!$S$179:$S$182,4),'Fase de Grupos'!$S$179:$S$182,0)),"—")
A17: ⚠️ The 8 best 3rd-place finishers also advance to the Round of 32. Those slots are determined after all groups complete and must be entered manually in the Bracket tab.

Sheet Bracket
A1: 🏆 FIFA WORLD CUP 2026 · KNOCKOUT BRACKET 🏆
A3: ✏️ Yellow cells = goals (90 min + ET combined) · Blue-grey rows = Penalty shootout score (only if tied after ET) · Blue-grey team cells = best 3rd-place qualifier — type the country name after the group stage
A6: ROUND OF 32 Jun 28 – Jul 3 | E6: ROUND OF 16 Jul 4 – 7 | I6: QUARTER-FINALS Jul 9 – 11 | M6: SEMI-FINALS Jul 14 – 15 | Q6: 🏆 FINAL 🏆 Jul 19 · New York / NJ | U6: SEMI-FINALS Jul 14 – 15 | Y6: QUARTER-FINALS Jul 9 – 11 | AC6: ROUND OF 16 Jul 4 – 7 | AG6: ROUND OF 32 Jun 28 – Jul 3
A8: Jun 28 · Los Angeles | AG8: Jul 1 · Seattle
A9: ='Clasificados'!$C$4 | B9: =RANDBETWEEN(0,4) | C9: =RANDBETWEEN(0,4) | D9: ='Clasificados'!$C$5 | AG9: ='Clasificados'!$B$10 | AH9: =RANDBETWEEN(0,4) | AI9: =RANDBETWEEN(0,4) | AJ9: New Zealand
A10: Pen → | B10: =RANDBETWEEN(3,7) | C10: =RANDBETWEEN(3,7) | D10: ← Pen | AG10: Pen → | AH10: =RANDBETWEEN(3,7) | AI10: =RANDBETWEEN(3,7) | AJ10: ← Pen
E11: Jul 4 · Houston | AC11: Jul 6 · Dallas
A12: Jun 29 · Houston | E12: =IF(AND($B$9<>"",$C$9<>"",$A$9<>"",$D$9<>""),IF($B$9>$C$9,$A$9,IF($C$9>$B$9,$D$9,IF(AND($B$10<>"",$C$10<>""),IF($B$10>$C$10,$A$9,IF($B$10<$C$10,$D$9,"TBD")),"TBD"))),"—") | F12: =RANDBETWEEN(0,4) | G12: =RANDBETWEEN(0,4) | H12: =IF(AND($B$13<>"",$C$13<>"",$A$13<>"",$D$13<>""),IF($B$13>$C$13,$A$13,IF($C$13>$B$13,$D$13,IF(AND($B$14<>"",$C$14<>""),IF($B$14>$C$14,$A$13,IF($B$14<$C$14,$D$13,"TBD")),"TBD"))),"—") | AC12: =IF(AND($AH$9<>"",$AI$9<>"",$AG$9<>"",$AJ$9<>""),IF($AH$9>$AI$9,$AG$9,IF($AI$9>$AH$9,$AJ$9,IF(AND($AH$10<>"",$AI$10<>""),IF($AH$10>$AI$10,$AG$9,IF($AH$10<$AI$10,$AJ$9,"TBD")),"TBD"))),"—") | AD12: =RANDBETWEEN(0,4) | AE12: =RANDBETWEEN(0,4) | AF12: =IF(AND($AH$13<>"",$AI$13<>"",$AG$13<>"",$AJ$13<>""),IF($AH$13>$AI$13,$AG$13,IF($AI$13>$AH$13,$AJ$13,IF(AND($AH$14<>"",$AI$14<>""),IF($AH$14>$AI$14,$AG$13,IF($AH$14<$AI$14,$AJ$13,"TBD")),"TBD"))),"—") | AG12: Jul 1 · San Francisco
A13: ='Clasificados'!$B$6 | B13: =RANDBETWEEN(0,4) | C13: =RANDBETWEEN(0,4) | D13: ='Clasificados'!$C$9 | E13: Pen → | F13: =RANDBETWEEN(3,7) | G13: =RANDBETWEEN(3,7) | H13: ← Pen | AC13: Pen → | AD13: =RANDBETWEEN(3,7) | AE13: =RANDBETWEEN(3,7) | AF13: ← Pen | AG13: ='Clasificados'!$B$7 | AH13: =RANDBETWEEN(0,4) | AI13: =RANDBETWEEN(0,4) | AJ13: Turkey
A14: Pen → | B14: =RANDBETWEEN(3,7) | C14: =RANDBETWEEN(3,7) | D14: ← Pen | AG14: Pen → | AH14: =RANDBETWEEN(3,7) | AI14: =RANDBETWEEN(3,7) | AJ14: ← Pen
I15: Jul 9 · Boston | Y15: Jul 11 · Miami
A16: Jun 29 · Boston | I16: =IF(AND($F$12<>"",$G$12<>"",$E$12<>"",$H$12<>""),IF($F$12>$G$12,$E$12,IF($G$12>$F$12,$H$12,IF(AND($F$13<>"",$G$13<>""),IF($F$13>$G$13,$E$12,IF($F$13<$G$13,$H$12,"TBD")),"TBD"))),"—") | J16: =RANDBETWEEN(0,4) | K16: =RANDBETWEEN(0,4) | L16: =IF(AND($F$20<>"",$G$20<>"",$E$20<>"",$H$20<>""),IF($F$20>$G$20,$E$20,IF($G$20>$F$20,$H$20,IF(AND($F$21<>"",$G$21<>""),IF($F$21>$G$21,$E$20,IF($F$21<$G$21,$H$20,"TBD")),"TBD"))),"—") | Y16: =IF(AND($AD$12<>"",$AE$12<>"",$AC$12<>"",$AF$12<>""),IF($AD$12>$AE$12,$AC$12,IF($AE$12>$AD$12,$AF$12,IF(AND($AD$13<>"",$AE$13<>""),IF($AD$13>$AE$13,$AC$12,IF($AD$13<$AE$13,$AF$12,"TBD")),"TBD"))),"—") | Z16: =RANDBETWEEN(0,4) | AA16: =RANDBETWEEN(0,4) | AB16: =IF(AND($AD$20<>"",$AE$20<>"",$AC$20<>"",$AF$20<>""),IF($AD$20>$AE$20,$AC$20,IF($AE$20>$AD$20,$AF$20,IF(AND($AD$21<>"",$AE$21<>""),IF($AD$21>$AE$21,$AC$20,IF($AD$21<$AE$21,$AF$20,"TBD")),"TBD"))),"—") | AG16: Jul 2 · Los Angeles
A17: ='Clasificados'!$B$8 | B17: =RANDBETWEEN(0,4) | C17: =RANDBETWEEN(0,4) | D17: Czech Republic | I17: Pen → | J17: =RANDBETWEEN(3,7) | K17: =RANDBETWEEN(3,7) | L17: ← Pen | Y17: Pen → | Z17: =RANDBETWEEN(3,7) | AA17: =RANDBETWEEN(3,7) | AB17: ← Pen | AG17: ='Clasificados'!$B$11 | AH17: =RANDBETWEEN(0,4) | AI17: =RANDBETWEEN(0,4) | AJ17: ='Clasificados'!$C$13
A18: Pen → | B18: =RANDBETWEEN(3,7) | C18: =RANDBETWEEN(3,7) | D18: ← Pen | AG18: Pen → | AH18: =RANDBETWEEN(3,7) | AI18: =RANDBETWEEN(3,7) | AJ18: ← Pen
E19: Jul 4 · Philadelphia | AC19: Jul 6 · Seattle
A20: Jun 29 · Monterrey | E20: =IF(AND($B$17<>"",$C$17<>"",$A$17<>"",$D$17<>""),IF($B$17>$C$17,$A$17,IF($C$17>$B$17,$D$17,IF(AND($B$18<>"",$C$18<>""),IF($B$18>$C$18,$A$17,IF($B$18<$C$18,$D$17,"TBD")),"TBD"))),"—") | F20: =RANDBETWEEN(0,4) | G20: =RANDBETWEEN(0,4) | H20: =IF(AND($B$21<>"",$C$21<>"",$A$21<>"",$D$21<>""),IF($B$21>$C$21,$A$21,IF($C$21>$B$21,$D$21,IF(AND($B$22<>"",$C$22<>""),IF($B$22>$C$22,$A$21,IF($B$22<$C$22,$D$21,"TBD")),"TBD"))),"—") | AC20: =IF(AND($AH$17<>"",$AI$17<>"",$AG$17<>"",$AJ$17<>""),IF($AH$17>$AI$17,$AG$17,IF($AI$17>$AH$17,$AJ$17,IF(AND($AH$18<>"",$AI$18<>""),IF($AH$18>$AI$18,$AG$17,IF($AH$18<$AI$18,$AJ$17,"TBD")),"TBD"))),"—") | AD20: =RANDBETWEEN(0,4) | AE20: =RANDBETWEEN(0,4) | AF20: =IF(AND($AH$21<>"",$AI$21<>"",$AG$21<>"",$AJ$21<>""),IF($AH$21>$AI$21,$AG$21,IF($AI$21>$AH$21,$AJ$21,IF(AND($AH$22<>"",$AI$22<>""),IF($AH$22>$AI$22,$AG$21,IF($AH$22<$AI$22,$AJ$21,"TBD")),"TBD"))),"—") | AG20: Jul 2 · Toronto
A21: ='Clasificados'!$B$9 | B21: =RANDBETWEEN(0,4) | C21: =RANDBETWEEN(0,4) | D21: ='Clasificados'!$C$6 | E21: Pen → | F21: =RANDBETWEEN(3,7) | G21: =RANDBETWEEN(3,7) | H21: ← Pen | AC21: Pen → | AD21: =RANDBETWEEN(3,7) | AE21: =RANDBETWEEN(3,7) | AF21: ← Pen | AG21: ='Clasificados'!$C$14 | AH21: =RANDBETWEEN(0,4) | AI21: =RANDBETWEEN(0,4) | AJ21: ='Clasificados'!$C$15
A22: Pen → | B22: =RANDBETWEEN(3,7) | C22: =RANDBETWEEN(3,7) | D22: ← Pen | AG22: Pen → | AH22: =RANDBETWEEN(3,7) | AI22: =RANDBETWEEN(3,7) | AJ22: ← Pen
M23: Jul 14 · Dallas | Q23: Jul 19 · New York/NJ · MetLife Stadium | U23: Jul 15 · Atlanta
A24: Jun 30 · Dallas | M24: =IF(AND($J$16<>"",$K$16<>"",$I$16<>"",$L$16<>""),IF($J$16>$K$16,$I$16,IF($K$16>$J$16,$L$16,IF(AND($J$17<>"",$K$17<>""),IF($J$17>$K$17,$I$16,IF($J$17<$K$17,$L$16,"TBD")),"TBD"))),"—") | N24: =RANDBETWEEN(0,4) | O24: =RANDBETWEEN(0,4) | P24: =IF(AND($J$32<>"",$K$32<>"",$I$32<>"",$L$32<>""),IF($J$32>$K$32,$I$32,IF($K$32>$J$32,$L$32,IF(AND($J$33<>"",$K$33<>""),IF($J$33>$K$33,$I$32,IF($J$33<$K$33,$L$32,"TBD")),"TBD"))),"—") | Q24: =IF(AND($N$24<>"",$O$24<>"",$M$24<>"",$P$24<>""),IF($N$24>$O$24,$M$24,IF($O$24>$N$24,$P$24,IF(AND($N$25<>"",$O$25<>""),IF($N$25>$O$25,$M$24,IF($N$25<$O$25,$P$24,"TBD")),"TBD"))),"—") | R24: =RANDBETWEEN(0,4) | S24: =RANDBETWEEN(0,4) | T24: =IF(AND($V$24<>"",$W$24<>"",$U$24<>"",$X$24<>""),IF($V$24>$W$24,$U$24,IF($W$24>$V$24,$X$24,IF(AND($V$25<>"",$W$25<>""),IF($V$25>$W$25,$U$24,IF($V$25<$W$25,$X$24,"TBD")),"TBD"))),"—") | U24: =IF(AND($Z$16<>"",$AA$16<>"",$Y$16<>"",$AB$16<>""),IF($Z$16>$AA$16,$Y$16,IF($AA$16>$Z$16,$AB$16,IF(AND($Z$17<>"",$AA$17<>""),IF($Z$17>$AA$17,$Y$16,IF($Z$17<$AA$17,$AB$16,"TBD")),"TBD"))),"—") | V24: =RANDBETWEEN(0,4) | W24: =RANDBETWEEN(0,4) | X24: =IF(AND($Z$32<>"",$AA$32<>"",$Y$32<>"",$AB$32<>""),IF($Z$32>$AA$32,$Y$32,IF($AA$32>$Z$32,$AB$32,IF(AND($Z$33<>"",$AA$33<>""),IF($Z$33>$AA$33,$Y$32,IF($Z$33<$AA$33,$AB$32,"TBD")),"TBD"))),"—") | AG24: Jul 2 · Vancouver
A25: ='Clasificados'!$C$8 | B25: =RANDBETWEEN(0,4) | C25: =RANDBETWEEN(0,4) | D25: ='Clasificados'!$C$12 | M25: Pen → | N25: =RANDBETWEEN(3,7) | O25: =RANDBETWEEN(3,7) | P25: ← Pen | Q25: Pen → | R25: =RANDBETWEEN(3,7) | S25: =RANDBETWEEN(3,7) | T25: ← Pen | U25: Pen → | V25: =RANDBETWEEN(3,7) | W25: =RANDBETWEEN(3,7) | X25: ← Pen | AG25: ='Clasificados'!$B$5 | AH25: =RANDBETWEEN(0,4) | AI25: =RANDBETWEEN(0,4) | AJ25: Qatar
A26: Pen → | B26: =RANDBETWEEN(3,7) | C26: =RANDBETWEEN(3,7) | D26: ← Pen | Q26: =IF($R$24<>"","🏆 "&IF(AND($R$24<>"",$S$24<>"",$Q$24<>"",$T$24<>""),IF($R$24>$S$24,$Q$24,IF($S$24>$R$24,$T$24,IF(AND($R$25<>"",$S$25<>""),IF($R$25>$S$25,$Q$24,IF($R$25<$S$25,$T$24,"TBD")),"TBD"))),"—")&" 🏆","🏆 WORLD CHAMPION 🏆") | AG26: Pen → | AH26: =RANDBETWEEN(3,7) | AI26: =RANDBETWEEN(3,7) | AJ26: ← Pen
E27: Jul 5 · New York/NJ | AC27: Jul 7 · Atlanta
A28: Jun 30 · New York/NJ | E28: =IF(AND($B$25<>"",$C$25<>"",$A$25<>"",$D$25<>""),IF($B$25>$C$25,$A$25,IF($C$25>$B$25,$D$25,IF(AND($B$26<>"",$C$26<>""),IF($B$26>$C$26,$A$25,IF($B$26<$C$26,$D$25,"TBD")),"TBD"))),"—") | F28: =RANDBETWEEN(0,4) | G28: =RANDBETWEEN(0,4) | H28: =IF(AND($B$29<>"",$C$29<>"",$A$29<>"",$D$29<>""),IF($B$29>$C$29,$A$29,IF($C$29>$B$29,$D$29,IF(AND($B$30<>"",$C$30<>""),IF($B$30>$C$30,$A$29,IF($B$30<$C$30,$D$29,"TBD")),"TBD"))),"—") | AC28: =IF(AND($AH$25<>"",$AI$25<>"",$AG$25<>"",$AJ$25<>""),IF($AH$25>$AI$25,$AG$25,IF($AI$25>$AH$25,$AJ$25,IF(AND($AH$26<>"",$AI$26<>""),IF($AH$26>$AI$26,$AG$25,IF($AH$26<$AI$26,$AJ$25,"TBD")),"TBD"))),"—") | AD28: =RANDBETWEEN(0,4) | AE28: =RANDBETWEEN(0,4) | AF28: =IF(AND($AH$29<>"",$AI$29<>"",$AG$29<>"",$AJ$29<>""),IF($AH$29>$AI$29,$AG$29,IF($AI$29>$AH$29,$AJ$29,IF(AND($AH$30<>"",$AI$30<>""),IF($AH$30>$AI$30,$AG$29,IF($AH$30<$AI$30,$AJ$29,"TBD")),"TBD"))),"—") | AG28: Jul 3 · Dallas
A29: ='Clasificados'!$B$12 | B29: =RANDBETWEEN(0,4) | C29: =RANDBETWEEN(0,4) | D29: Norway | E29: Pen → | F29: =RANDBETWEEN(3,7) | G29: =RANDBETWEEN(3,7) | H29: ← Pen | AC29: Pen → | AD29: =RANDBETWEEN(3,7) | AE29: =RANDBETWEEN(3,7) | AF29: ← Pen | AG29: ='Clasificados'!$C$7 | AH29: =RANDBETWEEN(0,4) | AI29: =RANDBETWEEN(0,4) | AJ29: ='Clasificados'!$C$10
A30: Pen → | B30: =RANDBETWEEN(3,7) | C30: =RANDBETWEEN(3,7) | D30: ← Pen | AG30: Pen → | AH30: =RANDBETWEEN(3,7) | AI30: =RANDBETWEEN(3,7) | AJ30: ← Pen
I31: Jul 10 · Los Angeles | Y31: Jul 11 · Kansas City
A32: Jun 30 · Mexico City | I32: =IF(AND($F$28<>"",$G$28<>"",$E$28<>"",$H$28<>""),IF($F$28>$G$28,$E$28,IF($G$28>$F$28,$H$28,IF(AND($F$29<>"",$G$29<>""),IF($F$29>$G$29,$E$28,IF($F$29<$G$29,$H$28,"TBD")),"TBD"))),"—") | J32: =RANDBETWEEN(0,4) | K32: =RANDBETWEEN(0,4) | L32: =IF(AND($F$36<>"",$G$36<>"",$E$36<>"",$H$36<>""),IF($F$36>$G$36,$E$36,IF($G$36>$F$36,$H$36,IF(AND($F$37<>"",$G$37<>""),IF($F$37>$G$37,$E$36,IF($F$37<$G$37,$H$36,"TBD")),"TBD"))),"—") | Y32: =IF(AND($AD$28<>"",$AE$28<>"",$AC$28<>"",$AF$28<>""),IF($AD$28>$AE$28,$AC$28,IF($AE$28>$AD$28,$AF$28,IF(AND($AD$29<>"",$AE$29<>""),IF($AD$29>$AE$29,$AC$28,IF($AD$29<$AE$29,$AF$28,"TBD")),"TBD"))),"—") | Z32: =RANDBETWEEN(0,4) | AA32: =RANDBETWEEN(0,4) | AB32: =IF(AND($AD$36<>"",$AE$36<>"",$AC$36<>"",$AF$36<>""),IF($AD$36>$AE$36,$AC$36,IF($AE$36>$AD$36,$AF$36,IF(AND($AD$37<>"",$AE$37<>""),IF($AD$37>$AE$37,$AC$36,IF($AD$37<$AE$37,$AF$36,"TBD")),"TBD"))),"—") | AG32: Jul 3 · Miami
A33: ='Clasificados'!$B$4 | B33: =RANDBETWEEN(0,4) | C33: =RANDBETWEEN(0,4) | D33: South Africa | I33: Pen → | J33: =RANDBETWEEN(3,7) | K33: =RANDBETWEEN(3,7) | L33: ← Pen | Y33: Pen → | Z33: =RANDBETWEEN(3,7) | AA33: =RANDBETWEEN(3,7) | AB33: ← Pen | AG33: ='Clasificados'!$B$13 | AH33: =RANDBETWEEN(0,4) | AI33: =RANDBETWEEN(0,4) | AJ33: ='Clasificados'!$C$11
A34: Pen → | B34: =RANDBETWEEN(3,7) | C34: =RANDBETWEEN(3,7) | D34: ← Pen | AG34: Pen → | AH34: =RANDBETWEEN(3,7) | AI34: =RANDBETWEEN(3,7) | AJ34: ← Pen
E35: Jul 5 · Mexico City | AC35: Jul 7 · Vancouver
A36: Jul 1 · Atlanta | E36: =IF(AND($B$33<>"",$C$33<>"",$A$33<>"",$D$33<>""),IF($B$33>$C$33,$A$33,IF($C$33>$B$33,$D$33,IF(AND($B$34<>"",$C$34<>""),IF($B$34>$C$34,$A$33,IF($B$34<$C$34,$D$33,"TBD")),"TBD"))),"—") | F36: =RANDBETWEEN(0,4) | G36: =RANDBETWEEN(0,4) | H36: =IF(AND($B$37<>"",$C$37<>"",$A$37<>"",$D$37<>""),IF($B$37>$C$37,$A$37,IF($C$37>$B$37,$D$37,IF(AND($B$38<>"",$C$38<>""),IF($B$38>$C$38,$A$37,IF($B$38<$C$38,$D$37,"TBD")),"TBD"))),"—") | AC36: =IF(AND($AH$33<>"",$AI$33<>"",$AG$33<>"",$AJ$33<>""),IF($AH$33>$AI$33,$AG$33,IF($AI$33>$AH$33,$AJ$33,IF(AND($AH$34<>"",$AI$34<>""),IF($AH$34>$AI$34,$AG$33,IF($AH$34<$AI$34,$AJ$33,"TBD")),"TBD"))),"—") | AD36: =RANDBETWEEN(0,4) | AE36: =RANDBETWEEN(0,4) | AF36: =IF(AND($AH$37<>"",$AI$37<>"",$AG$37<>"",$AJ$37<>""),IF($AH$37>$AI$37,$AG$37,IF($AI$37>$AH$37,$AJ$37,IF(AND($AH$38<>"",$AI$38<>""),IF($AH$38>$AI$38,$AG$37,IF($AH$38<$AI$38,$AJ$37,"TBD")),"TBD"))),"—") | AG36: Jul 3 · Kansas City
A37: ='Clasificados'!$B$15 | B37: =RANDBETWEEN(0,4) | C37: =RANDBETWEEN(0,4) | D37: Ghana | E37: Pen → | F37: =RANDBETWEEN(3,7) | G37: =RANDBETWEEN(3,7) | H37: ← Pen | AC37: Pen → | AD37: =RANDBETWEEN(3,7) | AE37: =RANDBETWEEN(3,7) | AF37: ← Pen | AG37: ='Clasificados'!$B$14 | AH37: =RANDBETWEEN(0,4) | AI37: =RANDBETWEEN(0,4) | AJ37: DR Congo
A38: Pen → | B38: =RANDBETWEEN(3,7) | C38: =RANDBETWEEN(3,7) | D38: ← Pen | AG38: Pen → | AH38: =RANDBETWEEN(3,7) | AI38: =RANDBETWEEN(3,7) | AJ38: ← Pen
Q42: THIRD PLACE MATCH
Q43: Jul 18 · Miami
Q44: =IF(AND($N$24<>"",$O$24<>"",$M$24<>"",$P$24<>""),IF($N$24<$O$24,$M$24,IF($O$24<$N$24,$P$24,IF(AND($N$25<>"",$O$25<>""),IF($N$25<$O$25,$M$24,IF($N$25>$O$25,$P$24,"TBD")),"TBD"))),"—") | R44: =RANDBETWEEN(0,4) | S44: =RANDBETWEEN(0,4) | T44: =IF(AND($V$24<>"",$W$24<>"",$U$24<>"",$X$24<>""),IF($V$24<$W$24,$U$24,IF($W$24<$V$24,$X$24,IF(AND($V$25<>"",$W$25<>""),IF($V$25<$W$25,$U$24,IF($V$25>$W$25,$X$24,"TBD")),"TBD"))),"—")
Q45: Pen → | R45: =RANDBETWEEN(3,7) | S45: =RANDBETWEEN(3,7) | T45: ← Pen

Sheet Referencias
A1: 📚 References / Fuentes
A2: All data sourced from the following public references as of April 1, 2026.
A3: Source | B3: URL | C3: Accessed | D3: Description
A4: FIFA Official | B4: https://www.fifa.com/en/tournaments/mens/worldcup/canadamexicousa2026/articles/match-schedule-fixtures-results-teams-stadiums | C4: Apr 1, 2026 | D4: Official match schedule and fixtures
A5: FOX Sports | B5: https://www.foxsports.com/stories/soccer/2026-world-cup-schedule-all-games-dates-matchups-how-watch | C5: Apr 1, 2026 | D5: Full broadcast schedule with dates, times and venues
A6: CNN Español | B6: https://cnnespanol.cnn.com/2026/04/01/deportes/grupos-zonas-copa-mundial-2026-orix | C6: Apr 1, 2026 | D6: Complete groups and match calendar (post-playoff)
A7: Marca | B7: https://www.marca.com/futbol/mundial/2026/04/01/estan-12-grupos-completos-mundial-falta-irak-bolivia.html | C7: Apr 1, 2026 | D7: 12 complete groups confirmed; Iraq & DR Congo qualify via inter-confederation playoff
A8: Wikipedia – 2026 FIFA World Cup | B8: https://en.wikipedia.org/wiki/2026_FIFA_World_Cup | C8: Apr 1, 2026 | D8: Tournament overview, format, host cities, qualification
A10: Tournament format: 48 teams · 12 groups of 4 · Top 2 per group + 8 best 3rd-place finishers → Round of 32 · 104 total matches · June 11 – July 19, 2026 · Host cities: USA, Canada, Mexico
A12: Generated by generate_quiniela.py · MIT License
